Workbook

Sheet START HERE
A1: FINANCIAL CAPACITY EVALUATION WORKBOOK
A2: Calculation and screening aid for evaluation committees — simple, traceable, and consistent.
A4: USE THIS ORDER — DO NOT START WITH THE RATIOS
A5: 1 | B5: Read the financial statements. | C5: Start with the Income Statement, then the Balance Sheet, then the Cash Flow Statement.
A6: 2 | B6: Use the STATEMENT MAP. | C6: Find the correct line item before entering any number.
A7: 3 | B7: Enter figures in yellow cells only. | C7: Leave missing figures blank. Do not guess.
A8: 4 | B8: Review RATIO RESULTS and DASHBOARD. | C8: These are screening aids, not final decisions.
A9: 5 | B9: Use FINDING BUILDER. | C9: Copy wording only after checking the source figures.
A11: THE PLAIN TEST
A12: Can the bidder make money? | B12: Check Gross Profit Margin and Net Profit Margin.
A13: Can the bidder pay bills? | B13: Check Current Ratio, Quick Ratio, Cash, Current Liabilities and Working Capital.
A14: Is the bidder too dependent on debt? | B14: Check Debt-to-Equity, Equity Ratio and Interest Cover where available.
A15: Is cash tied up? | B15: Check Receivables Turnover, Collection Days, Work in Progress and related-party balances.
A17: COMMITTEE RULE
A18: Every figure must have a home: statement, year and line item. If the figure cannot be traced, do not use it. A ratio is a signal, not a verdict.

Sheet DATA ENTRY
A1: DATA ENTRY — TYPE ONLY IN YELLOW CELLS
A2: Enter one row per bidder and financial year. Use the same financial year for income statement and balance sheet figures where possible. If a figure is missing, leave it blank and record the limitation in Source Note/Page.
A5: Record No. | B5: Bidder / Company | C5: Sector | D5: Financial Year | E5: Statement Status | F5: Contract Value (TTD) | G5: Revenue | H5: Cost of Sales / Direct Costs | I5: Gross Profit (if shown) | J5: Net Profit After Tax | K5: Current Assets | L5: Cash at Bank | M5: Trade Receivables - Current Year | N5: Trade Receivables - Prior Year | O5: Inventory / Stock | P5: Work in Progress | Q5: Total Assets | R5: Current Liabilities | S5: Non-current Liabilities | T5: Total Liabilities | U5: Total Equity | V5: Operating Profit / EBIT | W5: Interest Expense | X5: Source Note / Page | Y5: Figure Check Complete?
A6: =IF($B6<>"",ROW()-5,"")
A7: =IF($B7<>"",ROW()-5,"")
A8: =IF($B8<>"",ROW()-5,"")
A9: =IF($B9<>"",ROW()-5,"")
A10: =IF($B10<>"",ROW()-5,"")
A11: =IF($B11<>"",ROW()-5,"")
A12: =IF($B12<>"",ROW()-5,"")
A13: =IF($B13<>"",ROW()-5,"")
A14: =IF($B14<>"",ROW()-5,"")
A15: =IF($B15<>"",ROW()-5,"")
A16: =IF($B16<>"",ROW()-5,"")
A17: =IF($B17<>"",ROW()-5,"")
... A35: =IF($B35<>"",ROW()-5,"")

Sheet RATIO RESULTS
A1: RATIO RESULTS — AUTOMATIC CALCULATION AND SCREENING
A2: Do not type here. This sheet calculates ratios from DATA ENTRY. Ratings are first-pass screening only and do not replace approved evaluation criteria.
A5: Record No. | B5: Bidder / Company | C5: Sector | D5: Year | E5: Statement Status | F5: Data Check | G5: Gross Profit Used | H5: Gross Profit Margin | I5: GPM Rating | J5: Net Profit Margin | K5: NPM Rating | L5: ROA | M5: ROA Rating | N5: ROE | O5: ROE Rating | P5: Current Ratio | Q5: CR Rating | R5: Quick Ratio | S5: QR Rating | T5: Debt-to-Equity | U5: D/E Rating | V5: Equity Ratio | W5: Equity Rating | X5: Receivables Turnover | Y5: Collection Days | Z5: Receivables Rating | AA5: Asset Turnover | AB5: Asset Rating | AC5: Working Capital | AD5: WC Rating | AE5: Interest Cover | AF5: ICR Rating | AG5: Overall Score | AH5: Overall Screening Rating | AI5: Main Flag
A6: =IF('DATA ENTRY'!$B6<>"",'DATA ENTRY'!$A6,"") | B6: =IF('DATA ENTRY'!$B6<>"",'DATA ENTRY'!$B6,"") | C6: =IF('DATA ENTRY'!$B6<>"",'DATA ENTRY'!$C6,"") | D6: =IF('DATA ENTRY'!$B6<>"",'DATA ENTRY'!$D6,"") | E6: =IF('DATA ENTRY'!$B6<>"",'DATA ENTRY'!$E6,"") | F6: =IF($B6="","",IF('DATA ENTRY'!$Y6="Yes","Checked",IF('DATA ENTRY'!$Y6="No","Needs check","Not marked"))) | G6: =IF($B6="","",IF('DATA ENTRY'!$I6<>"",'DATA ENTRY'!$I6,IF(AND('DATA ENTRY'!$G6<>"",'DATA ENTRY'!$H6<>""),'DATA ENTRY'!$G6-'DATA ENTRY'!$H6,""))) | H6: =IF(OR($B6="",$G6="",'DATA ENTRY'!$G6=""),"",IFERROR($G6/'DATA ENTRY'!$G6,"")) | I6: =IF($B6="","",IF($H6="","Not entered",IF($H6>=0.25,"Strong",IF($H6>=0.15,"Adequate",IF($H6>=0.05,"Caution","High-risk"))))) | J6: =IF(OR($B6="",'DATA ENTRY'!$J6="",'DATA ENTRY'!$G6=""),"",IFERROR('DATA ENTRY'!$J6/'DATA ENTRY'!$G6,"")) | K6: =IF($B6="","",IF($J6="","Not entered",IF($J6>=0.08,"Strong",IF($J6>=0.03,"Adequate",IF($J6>=0,"Caution","High-risk"))))) | L6: =IF(OR($B6="",'DATA ENTRY'!$J6="",'DATA ENTRY'!$Q6=""),"",IFERROR('DATA ENTRY'!$J6/'DATA ENTRY'!$Q6,"")) | M6: =IF($B6="","",IF($L6="","Not entered",IF($L6>=0.1,"Strong",IF($L6>=0.05,"Adequate",IF($L6>=0,"Caution","High-risk"))))) | N6: =IF(OR($B6="",'DATA ENTRY'!$J6="",'DATA ENTRY'!$U6="",'DATA ENTRY'!$U6<=0),"",IFERROR('DATA ENTRY'!$J6/'DATA ENTRY'!$U6,"")) | O6: =IF($B6="","",IF(OR('DATA ENTRY'!$J6="",'DATA ENTRY'!$U6=""),"Not entered",IF('DATA ENTRY'!$U6<=0,"High-risk",IF($N6>=0.15,"Strong",IF($N6>=0.08,"Adequate",IF($N6>=0,"Caution","High-risk")))))) | P6: =IF(OR($B6="",'DATA ENTRY'!$K6="",'DATA ENTRY'!$R6=""),"",IFERROR('DATA ENTRY'!$K6/'DATA ENTRY'!$R6,"")) | Q6: =IF($B6="","",IF($P6="","Not entered",IF($P6>=1.5,"Strong",IF($P6>=1.2,"Adequate",IF($P6>=1,"Caution","High-risk"))))) | R6: =IF(OR($B6="",'DATA ENTRY'!$K6="",'DATA ENTRY'!$R6=""),"",IFERROR(('DATA ENTRY'!$K6-IF('DATA ENTRY'!$O6="",0,'DATA ENTRY'!$O6))/'DATA ENTRY'!$R6,"")) | S6: =IF($B6="","",IF($R6="","Not entered",IF($R6>=1,"Strong",IF($R6>=0.8,"Adequate",IF($R6>=0.6,"Caution","High-risk"))))) | T6: =IF(OR($B6="",'DATA ENTRY'!$T6="",'DATA ENTRY'!$U6="",'DATA ENTRY'!$U6<=0),"",IFERROR('DATA ENTRY'!$T6/'DATA ENTRY'!$U6,"")) | U6: =IF($B6="","",IF(OR('DATA ENTRY'!$T6="",'DATA ENTRY'!$U6=""),"Not entered",IF('DATA ENTRY'!$U6<=0,"High-risk",IF($T6<=1,"Strong",IF($T6<=1.5,"Adequate",IF($T6<=2,"Caution","High-risk")))))) | V6: =IF(OR($B6="",'DATA ENTRY'!$U6="",'DATA ENTRY'!$Q6=""),"",IFERROR('DATA ENTRY'!$U6/'DATA ENTRY'!$Q6,"")) | W6: =IF($B6="","",IF($V6="","Not entered",IF($V6>=0.5,"Strong",IF($V6>=0.3,"Adequate",IF($V6>=0.2,"Caution","High-risk"))))) | X6: =IF(OR($B6="",'DATA ENTRY'!$G6="",'DATA ENTRY'!$M6=""),"",IF('DATA ENTRY'!$N6<>"",'DATA ENTRY'!$G6/AVERAGE('DATA ENTRY'!$M6,'DATA ENTRY'!$N6),IFERROR('DATA ENTRY'!$G6/'DATA ENTRY'!$M6,""))) | Y6: =IF($X6="","",IFERROR(365/$X6,"")) | Z6: =IF($B6="","",IF($X6="","Not entered",IF($Y6<=60,"Strong",IF($Y6<=90,"Adequate",IF($Y6<=120,"Caution","High-risk"))))) | AA6: =IF(OR($B6="",'DATA ENTRY'!$G6="",'DATA ENTRY'!$Q6=""),"",IFERROR('DATA ENTRY'!$G6/'DATA ENTRY'!$Q6,"")) | AB6: =IF($B6="","",IF($AA6="","Not entered",IF($AA6>=1.5,"Strong",IF($AA6>=1,"Adequate",IF($AA6>=0.5,"Caution","High-risk"))))) | AC6: =IF(OR($B6="",'DATA ENTRY'!$K6="",'DATA ENTRY'!$R6=""),"",'DATA ENTRY'!$K6-'DATA ENTRY'!$R6) | AD6: =IF($B6="","",IF($AC6="","Not entered",IF($AC6<0,"High-risk",IF($AC6=0,"Caution",IF('DATA ENTRY'!$L6="","Adequate",IFERROR(IF('DATA ENTRY'!$L6/'DATA ENTRY'!$R6>=0.25,"Strong","Adequate"),"Adequate")))))) | AE6: =IF($B6="","",IF(OR('DATA ENTRY'!$W6="",'DATA ENTRY'!$W6=0),"N/A",IF('DATA ENTRY'!$V6="","",IFERROR('DATA ENTRY'!$V6/'DATA ENTRY'!$W6,"")))) | AF6: =IF($B6="","",IF($AE6="N/A","Not applicable",IF($AE6="","Not entered",IF($AE6>=4,"Strong",IF($AE6>=2.5,"Adequate",IF($AE6>=1.5,"Caution","High-risk")))))) | AG6: =IF($B6="","",IFERROR(ROUND((COUNTIF($I6:$AF6,"Strong")*4+COUNTIF($I6:$AF6,"Adequate")*3+COUNTIF($I6:$AF6,"Caution")*2+COUNTIF($I6:$AF6,"High-risk")*1)/(COUNTIF($I6:$AF6,"Strong")+COUNTIF($I6:$AF6,"Adequate")+COUNTIF($I6:$AF6,"Caution")+COUNTIF($I6:$AF6,"High-risk")),2),"")) | AH6: =IF($B6="","",IF(AND(ISNUMBER('DATA ENTRY'!$U6),'DATA ENTRY'!$U6<=0),"Financially stretched",IF($AG6="","Insufficient data",IF(AND(ISNUMBER('DATA ENTRY'!$J6),'DATA ENTRY'!$J6<0),IF($AG6>=2,"Adequate with caution","Financially stretched"),IF($AG6>=3.5,"Financially strong",IF($AG6>=2.75,"Financially adequate",IF($AG6>=2,"Adequate with caution","Financially stretched"))))))) | AI6: =IF($B6="","",IF(AND(ISNUMBER('DATA ENTRY'!$U6),'DATA ENTRY'!$U6<=0),"Negative equity — possible insolvency",IF(AND(ISNUMBER('DATA ENTRY'!$J6),'DATA ENTRY'!$J6<0),"Loss position",IF(AND(ISNUMBER($P6),$P6<1),"Current liabilities exceed current assets",IF(AND(ISNUMBER($T6),$T6>2),"High leverage",IF(AND(ISNUMBER($Y6),$Y6>120),"Slow receivables collection",IF(AND(ISNUMBER($AC6),$AC6<0),"Negative working capital",IF(OR('DATA ENTRY'!$E6="Unaudited",'DATA ENTRY'!$E6="Banker Letter Only",'DATA ENTRY'!$E6="Management Accounts"),"Statement status limits weight on ratios","No major red flag from entered ratios"))))))))
A7: =IF('DATA ENTRY'!$B7<>"",'DATA ENTRY'!$A7,"") | B7: =IF('DATA ENTRY'!$B7<>"",'DATA ENTRY'!$B7,"") | C7: =IF('DATA ENTRY'!$B7<>"",'DATA ENTRY'!$C7,"") | D7: =IF('DATA ENTRY'!$B7<>"",'DATA ENTRY'!$D7,"") | E7: =IF('DATA ENTRY'!$B7<>"",'DATA ENTRY'!$E7,"") | F7: =IF($B7="","",IF('DATA ENTRY'!$Y7="Yes","Checked",IF('DATA ENTRY'!$Y7="No","Needs check","Not marked"))) | G7: =IF($B7="","",IF('DATA ENTRY'!$I7<>"",'DATA ENTRY'!$I7,IF(AND('DATA ENTRY'!$G7<>"",'DATA ENTRY'!$H7<>""),'DATA ENTRY'!$G7-'DATA ENTRY'!$H7,""))) | H7: =IF(OR($B7="",$G7="",'DATA ENTRY'!$G7=""),"",IFERROR($G7/'DATA ENTRY'!$G7,"")) | I7: =IF($B7="","",IF($H7="","Not entered",IF($H7>=0.25,"Strong",IF($H7>=0.15,"Adequate",IF($H7>=0.05,"Caution","High-risk"))))) | J7: =IF(OR($B7="",'DATA ENTRY'!$J7="",'DATA ENTRY'!$G7=""),"",IFERROR('DATA ENTRY'!$J7/'DATA ENTRY'!$G7,"")) | K7: =IF($B7="","",IF($J7="","Not entered",IF($J7>=0.08,"Strong",IF($J7>=0.03,"Adequate",IF($J7>=0,"Caution","High-risk"))))) | L7: =IF(OR($B7="",'DATA ENTRY'!$J7="",'DATA ENTRY'!$Q7=""),"",IFERROR('DATA ENTRY'!$J7/'DATA ENTRY'!$Q7,"")) | M7: =IF($B7="","",IF($L7="","Not entered",IF($L7>=0.1,"Strong",IF($L7>=0.05,"Adequate",IF($L7>=0,"Caution","High-risk"))))) | N7: =IF(OR($B7="",'DATA ENTRY'!$J7="",'DATA ENTRY'!$U7="",'DATA ENTRY'!$U7<=0),"",IFERROR('DATA ENTRY'!$J7/'DATA ENTRY'!$U7,"")) | O7: =IF($B7="","",IF(OR('DATA ENTRY'!$J7="",'DATA ENTRY'!$U7=""),"Not entered",IF('DATA ENTRY'!$U7<=0,"High-risk",IF($N7>=0.15,"Strong",IF($N7>=0.08,"Adequate",IF($N7>=0,"Caution","High-risk")))))) | P7: =IF(OR($B7="",'DATA ENTRY'!$K7="",'DATA ENTRY'!$R7=""),"",IFERROR('DATA ENTRY'!$K7/'DATA ENTRY'!$R7,"")) | Q7: =IF($B7="","",IF($P7="","Not entered",IF($P7>=1.5,"Strong",IF($P7>=1.2,"Adequate",IF($P7>=1,"Caution","High-risk"))))) | R7: =IF(OR($B7="",'DATA ENTRY'!$K7="",'DATA ENTRY'!$R7=""),"",IFERROR(('DATA ENTRY'!$K7-IF('DATA ENTRY'!$O7="",0,'DATA ENTRY'!$O7))/'DATA ENTRY'!$R7,"")) | S7: =IF($B7="","",IF($R7="","Not entered",IF($R7>=1,"Strong",IF($R7>=0.8,"Adequate",IF($R7>=0.6,"Caution","High-risk"))))) | T7: =IF(OR($B7="",'DATA ENTRY'!$T7="",'DATA ENTRY'!$U7="",'DATA ENTRY'!$U7<=0),"",IFERROR('DATA ENTRY'!$T7/'DATA ENTRY'!$U7,"")) | U7: =IF($B7="","",IF(OR('DATA ENTRY'!$T7="",'DATA ENTRY'!$U7=""),"Not entered",IF('DATA ENTRY'!$U7<=0,"High-risk",IF($T7<=1,"Strong",IF($T7<=1.5,"Adequate",IF($T7<=2,"Caution","High-risk")))))) | V7: =IF(OR($B7="",'DATA ENTRY'!$U7="",'DATA ENTRY'!$Q7=""),"",IFERROR('DATA ENTRY'!$U7/'DATA ENTRY'!$Q7,"")) | W7: =IF($B7="","",IF($V7="","Not entered",IF($V7>=0.5,"Strong",IF($V7>=0.3,"Adequate",IF($V7>=0.2,"Caution","High-risk"))))) | X7: =IF(OR($B7="",'DATA ENTRY'!$G7="",'DATA ENTRY'!$M7=""),"",IF('DATA ENTRY'!$N7<>"",'DATA ENTRY'!$G7/AVERAGE('DATA ENTRY'!$M7,'DATA ENTRY'!$N7),IFERROR('DATA ENTRY'!$G7/'DATA ENTRY'!$M7,""))) | Y7: =IF($X7="","",IFERROR(365/$X7,"")) | Z7: =IF($B7="","",IF($X7="","Not entered",IF($Y7<=60,"Strong",IF($Y7<=90,"Adequate",IF($Y7<=120,"Caution","High-risk"))))) | AA7: =IF(OR($B7="",'DATA ENTRY'!$G7="",'DATA ENTRY'!$Q7=""),"",IFERROR('DATA ENTRY'!$G7/'DATA ENTRY'!$Q7,"")) | AB7: =IF($B7="","",IF($AA7="","Not entered",IF($AA7>=1.5,"Strong",IF($AA7>=1,"Adequate",IF($AA7>=0.5,"Caution","High-risk"))))) | AC7: =IF(OR($B7="",'DATA ENTRY'!$K7="",'DATA ENTRY'!$R7=""),"",'DATA ENTRY'!$K7-'DATA ENTRY'!$R7) | AD7: =IF($B7="","",IF($AC7="","Not entered",IF($AC7<0,"High-risk",IF($AC7=0,"Caution",IF('DATA ENTRY'!$L7="","Adequate",IFERROR(IF('DATA ENTRY'!$L7/'DATA ENTRY'!$R7>=0.25,"Strong","Adequate"),"Adequate")))))) | AE7: =IF($B7="","",IF(OR('DATA ENTRY'!$W7="",'DATA ENTRY'!$W7=0),"N/A",IF('DATA ENTRY'!$V7="","",IFERROR('DATA ENTRY'!$V7/'DATA ENTRY'!$W7,"")))) | AF7: =IF($B7="","",IF($AE7="N/A","Not applicable",IF($AE7="","Not entered",IF($AE7>=4,"Strong",IF($AE7>=2.5,"Adequate",IF($AE7>=1.5,"Caution","High-risk")))))) | AG7: =IF($B7="","",IFERROR(ROUND((COUNTIF($I7:$AF7,"Strong")*4+COUNTIF($I7:$AF7,"Adequate")*3+COUNTIF($I7:$AF7,"Caution")*2+COUNTIF($I7:$AF7,"High-risk")*1)/(COUNTIF($I7:$AF7,"Strong")+COUNTIF($I7:$AF7,"Adequate")+COUNTIF($I7:$AF7,"Caution")+COUNTIF($I7:$AF7,"High-risk")),2),"")) | AH7: =IF($B7="","",IF(AND(ISNUMBER('DATA ENTRY'!$U7),'DATA ENTRY'!$U7<=0),"Financially stretched",IF($AG7="","Insufficient data",IF(AND(ISNUMBER('DATA ENTRY'!$J7),'DATA ENTRY'!$J7<0),IF($AG7>=2,"Adequate with caution","Financially stretched"),IF($AG7>=3.5,"Financially strong",IF($AG7>=2.75,"Financially adequate",IF($AG7>=2,"Adequate with caution","Financially stretched"))))))) | AI7: =IF($B7="","",IF(AND(ISNUMBER('DATA ENTRY'!$U7),'DATA ENTRY'!$U7<=0),"Negative equity — possible insolvency",IF(AND(ISNUMBER('DATA ENTRY'!$J7),'DATA ENTRY'!$J7<0),"Loss position",IF(AND(ISNUMBER($P7),$P7<1),"Current liabilities exceed current assets",IF(AND(ISNUMBER($T7),$T7>2),"High leverage",IF(AND(ISNUMBER($Y7),$Y7>120),"Slow receivables collection",IF(AND(ISNUMBER($AC7),$AC7<0),"Negative working capital",IF(OR('DATA ENTRY'!$E7="Unaudited",'DATA ENTRY'!$E7="Banker Letter Only",'DATA ENTRY'!$E7="Management Accounts"),"Statement status limits weight on ratios","No major red flag from entered ratios"))))))))
A8: =IF('DATA ENTRY'!$B8<>"",'DATA ENTRY'!$A8,"") | B8: =IF('DATA ENTRY'!$B8<>"",'DATA ENTRY'!$B8,"") | C8: =IF('DATA ENTRY'!$B8<>"",'DATA ENTRY'!$C8,"") | D8: =IF('DATA ENTRY'!$B8<>"",'DATA ENTRY'!$D8,"") | E8: =IF('DATA ENTRY'!$B8<>"",'DATA ENTRY'!$E8,"") | F8: =IF($B8="","",IF('DATA ENTRY'!$Y8="Yes","Checked",IF('DATA ENTRY'!$Y8="No","Needs check","Not marked"))) | G8: =IF($B8="","",IF('DATA ENTRY'!$I8<>"",'DATA ENTRY'!$I8,IF(AND('DATA ENTRY'!$G8<>"",'DATA ENTRY'!$H8<>""),'DATA ENTRY'!$G8-'DATA ENTRY'!$H8,""))) | H8: =IF(OR($B8="",$G8="",'DATA ENTRY'!$G8=""),"",IFERROR($G8/'DATA ENTRY'!$G8,"")) | I8: =IF($B8="","",IF($H8="","Not entered",IF($H8>=0.25,"Strong",IF($H8>=0.15,"Adequate",IF($H8>=0.05,"Caution","High-risk"))))) | J8: =IF(OR($B8="",'DATA ENTRY'!$J8="",'DATA ENTRY'!$G8=""),"",IFERROR('DATA ENTRY'!$J8/'DATA ENTRY'!$G8,"")) | K8: =IF($B8="","",IF($J8="","Not entered",IF($J8>=0.08,"Strong",IF($J8>=0.03,"Adequate",IF($J8>=0,"Caution","High-risk"))))) | L8: =IF(OR($B8="",'DATA ENTRY'!$J8="",'DATA ENTRY'!$Q8=""),"",IFERROR('DATA ENTRY'!$J8/'DATA ENTRY'!$Q8,"")) | M8: =IF($B8="","",IF($L8="","Not entered",IF($L8>=0.1,"Strong",IF($L8>=0.05,"Adequate",IF($L8>=0,"Caution","High-risk"))))) | N8: =IF(OR($B8="",'DATA ENTRY'!$J8="",'DATA ENTRY'!$U8="",'DATA ENTRY'!$U8<=0),"",IFERROR('DATA ENTRY'!$J8/'DATA ENTRY'!$U8,"")) | O8: =IF($B8="","",IF(OR('DATA ENTRY'!$J8="",'DATA ENTRY'!$U8=""),"Not entered",IF('DATA ENTRY'!$U8<=0,"High-risk",IF($N8>=0.15,"Strong",IF($N8>=0.08,"Adequate",IF($N8>=0,"Caution","High-risk")))))) | P8: =IF(OR($B8="",'DATA ENTRY'!$K8="",'DATA ENTRY'!$R8=""),"",IFERROR('DATA ENTRY'!$K8/'DATA ENTRY'!$R8,"")) | Q8: =IF($B8="","",IF($P8="","Not entered",IF($P8>=1.5,"Strong",IF($P8>=1.2,"Adequate",IF($P8>=1,"Caution","High-risk"))))) | R8: =IF(OR($B8="",'DATA ENTRY'!$K8="",'DATA ENTRY'!$R8=""),"",IFERROR(('DATA ENTRY'!$K8-IF('DATA ENTRY'!$O8="",0,'DATA ENTRY'!$O8))/'DATA ENTRY'!$R8,"")) | S8: =IF($B8="","",IF($R8="","Not entered",IF($R8>=1,"Strong",IF($R8>=0.8,"Adequate",IF($R8>=0.6,"Caution","High-risk"))))) | T8: =IF(OR($B8="",'DATA ENTRY'!$T8="",'DATA ENTRY'!$U8="",'DATA ENTRY'!$U8<=0),"",IFERROR('DATA ENTRY'!$T8/'DATA ENTRY'!$U8,"")) | U8: =IF($B8="","",IF(OR('DATA ENTRY'!$T8="",'DATA ENTRY'!$U8=""),"Not entered",IF('DATA ENTRY'!$U8<=0,"High-risk",IF($T8<=1,"Strong",IF($T8<=1.5,"Adequate",IF($T8<=2,"Caution","High-risk")))))) | V8: =IF(OR($B8="",'DATA ENTRY'!$U8="",'DATA ENTRY'!$Q8=""),"",IFERROR('DATA ENTRY'!$U8/'DATA ENTRY'!$Q8,"")) | W8: =IF($B8="","",IF($V8="","Not entered",IF($V8>=0.5,"Strong",IF($V8>=0.3,"Adequate",IF($V8>=0.2,"Caution","High-risk"))))) | X8: =IF(OR($B8="",'DATA ENTRY'!$G8="",'DATA ENTRY'!$M8=""),"",IF('DATA ENTRY'!$N8<>"",'DATA ENTRY'!$G8/AVERAGE('DATA ENTRY'!$M8,'DATA ENTRY'!$N8),IFERROR('DATA ENTRY'!$G8/'DATA ENTRY'!$M8,""))) | Y8: =IF($X8="","",IFERROR(365/$X8,"")) | Z8: =IF($B8="","",IF($X8="","Not entered",IF($Y8<=60,"Strong",IF($Y8<=90,"Adequate",IF($Y8<=120,"Caution","High-risk"))))) | AA8: =IF(OR($B8="",'DATA ENTRY'!$G8="",'DATA ENTRY'!$Q8=""),"",IFERROR('DATA ENTRY'!$G8/'DATA ENTRY'!$Q8,"")) | AB8: =IF($B8="","",IF($AA8="","Not entered",IF($AA8>=1.5,"Strong",IF($AA8>=1,"Adequate",IF($AA8>=0.5,"Caution","High-risk"))))) | AC8: =IF(OR($B8="",'DATA ENTRY'!$K8="",'DATA ENTRY'!$R8=""),"",'DATA ENTRY'!$K8-'DATA ENTRY'!$R8) | AD8: =IF($B8="","",IF($AC8="","Not entered",IF($AC8<0,"High-risk",IF($AC8=0,"Caution",IF('DATA ENTRY'!$L8="","Adequate",IFERROR(IF('DATA ENTRY'!$L8/'DATA ENTRY'!$R8>=0.25,"Strong","Adequate"),"Adequate")))))) | AE8: =IF($B8="","",IF(OR('DATA ENTRY'!$W8="",'DATA ENTRY'!$W8=0),"N/A",IF('DATA ENTRY'!$V8="","",IFERROR('DATA ENTRY'!$V8/'DATA ENTRY'!$W8,"")))) | AF8: =IF($B8="","",IF($AE8="N/A","Not applicable",IF($AE8="","Not entered",IF($AE8>=4,"Strong",IF($AE8>=2.5,"Adequate",IF($AE8>=1.5,"Caution","High-risk")))))) | AG8: =IF($B8="","",IFERROR(ROUND((COUNTIF($I8:$AF8,"Strong")*4+COUNTIF($I8:$AF8,"Adequate")*3+COUNTIF($I8:$AF8,"Caution")*2+COUNTIF($I8:$AF8,"High-risk")*1)/(COUNTIF($I8:$AF8,"Strong")+COUNTIF($I8:$AF8,"Adequate")+COUNTIF($I8:$AF8,"Caution")+COUNTIF($I8:$AF8,"High-risk")),2),"")) | AH8: =IF($B8="","",IF(AND(ISNUMBER('DATA ENTRY'!$U8),'DATA ENTRY'!$U8<=0),"Financially stretched",IF($AG8="","Insufficient data",IF(AND(ISNUMBER('DATA ENTRY'!$J8),'DATA ENTRY'!$J8<0),IF($AG8>=2,"Adequate with caution","Financially stretched"),IF($AG8>=3.5,"Financially strong",IF($AG8>=2.75,"Financially adequate",IF($AG8>=2,"Adequate with caution","Financially stretched"))))))) | AI8: =IF($B8="","",IF(AND(ISNUMBER('DATA ENTRY'!$U8),'DATA ENTRY'!$U8<=0),"Negative equity — possible insolvency",IF(AND(ISNUMBER('DATA ENTRY'!$J8),'DATA ENTRY'!$J8<0),"Loss position",IF(AND(ISNUMBER($P8),$P8<1),"Current liabilities exceed current assets",IF(AND(ISNUMBER($T8),$T8>2),"High leverage",IF(AND(ISNUMBER($Y8),$Y8>120),"Slow receivables collection",IF(AND(ISNUMBER($AC8),$AC8<0),"Negative working capital",IF(OR('DATA ENTRY'!$E8="Unaudited",'DATA ENTRY'!$E8="Banker Letter Only",'DATA ENTRY'!$E8="Management Accounts"),"Statement status limits weight on ratios","No major red flag from entered ratios"))))))))
A9: =IF('DATA ENTRY'!$B9<>"",'DATA ENTRY'!$A9,"") | B9: =IF('DATA ENTRY'!$B9<>"",'DATA ENTRY'!$B9,"") | C9: =IF('DATA ENTRY'!$B9<>"",'DATA ENTRY'!$C9,"") | D9: =IF('DATA ENTRY'!$B9<>"",'DATA ENTRY'!$D9,"") | E9: =IF('DATA ENTRY'!$B9<>"",'DATA ENTRY'!$E9,"") | F9: =IF($B9="","",IF('DATA ENTRY'!$Y9="Yes","Checked",IF('DATA ENTRY'!$Y9="No","Needs check","Not marked"))) | G9: =IF($B9="","",IF('DATA ENTRY'!$I9<>"",'DATA ENTRY'!$I9,IF(AND('DATA ENTRY'!$G9<>"",'DATA ENTRY'!$H9<>""),'DATA ENTRY'!$G9-'DATA ENTRY'!$H9,""))) | H9: =IF(OR($B9="",$G9="",'DATA ENTRY'!$G9=""),"",IFERROR($G9/'DATA ENTRY'!$G9,"")) | I9: =IF($B9="","",IF($H9="","Not entered",IF($H9>=0.25,"Strong",IF($H9>=0.15,"Adequate",IF($H9>=0.05,"Caution","High-risk"))))) | J9: =IF(OR($B9="",'DATA ENTRY'!$J9="",'DATA ENTRY'!$G9=""),"",IFERROR('DATA ENTRY'!$J9/'DATA ENTRY'!$G9,"")) | K9: =IF($B9="","",IF($J9="","Not entered",IF($J9>=0.08,"Strong",IF($J9>=0.03,"Adequate",IF($J9>=0,"Caution","High-risk"))))) | L9: =IF(OR($B9="",'DATA ENTRY'!$J9="",'DATA ENTRY'!$Q9=""),"",IFERROR('DATA ENTRY'!$J9/'DATA ENTRY'!$Q9,"")) | M9: =IF($B9="","",IF($L9="","Not entered",IF($L9>=0.1,"Strong",IF($L9>=0.05,"Adequate",IF($L9>=0,"Caution","High-risk"))))) | N9: =IF(OR($B9="",'DATA ENTRY'!$J9="",'DATA ENTRY'!$U9="",'DATA ENTRY'!$U9<=0),"",IFERROR('DATA ENTRY'!$J9/'DATA ENTRY'!$U9,"")) | O9: =IF($B9="","",IF(OR('DATA ENTRY'!$J9="",'DATA ENTRY'!$U9=""),"Not entered",IF('DATA ENTRY'!$U9<=0,"High-risk",IF($N9>=0.15,"Strong",IF($N9>=0.08,"Adequate",IF($N9>=0,"Caution","High-risk")))))) | P9: =IF(OR($B9="",'DATA ENTRY'!$K9="",'DATA ENTRY'!$R9=""),"",IFERROR('DATA ENTRY'!$K9/'DATA ENTRY'!$R9,"")) | Q9: =IF($B9="","",IF($P9="","Not entered",IF($P9>=1.5,"Strong",IF($P9>=1.2,"Adequate",IF($P9>=1,"Caution","High-risk"))))) | R9: =IF(OR($B9="",'DATA ENTRY'!$K9="",'DATA ENTRY'!$R9=""),"",IFERROR(('DATA ENTRY'!$K9-IF('DATA ENTRY'!$O9="",0,'DATA ENTRY'!$O9))/'DATA ENTRY'!$R9,"")) | S9: =IF($B9="","",IF($R9="","Not entered",IF($R9>=1,"Strong",IF($R9>=0.8,"Adequate",IF($R9>=0.6,"Caution","High-risk"))))) | T9: =IF(OR($B9="",'DATA ENTRY'!$T9="",'DATA ENTRY'!$U9="",'DATA ENTRY'!$U9<=0),"",IFERROR('DATA ENTRY'!$T9/'DATA ENTRY'!$U9,"")) | U9: =IF($B9="","",IF(OR('DATA ENTRY'!$T9="",'DATA ENTRY'!$U9=""),"Not entered",IF('DATA ENTRY'!$U9<=0,"High-risk",IF($T9<=1,"Strong",IF($T9<=1.5,"Adequate",IF($T9<=2,"Caution","High-risk")))))) | V9: =IF(OR($B9="",'DATA ENTRY'!$U9="",'DATA ENTRY'!$Q9=""),"",IFERROR('DATA ENTRY'!$U9/'DATA ENTRY'!$Q9,"")) | W9: =IF($B9="","",IF($V9="","Not entered",IF($V9>=0.5,"Strong",IF($V9>=0.3,"Adequate",IF($V9>=0.2,"Caution","High-risk"))))) | X9: =IF(OR($B9="",'DATA ENTRY'!$G9="",'DATA ENTRY'!$M9=""),"",IF('DATA ENTRY'!$N9<>"",'DATA ENTRY'!$G9/AVERAGE('DATA ENTRY'!$M9,'DATA ENTRY'!$N9),IFERROR('DATA ENTRY'!$G9/'DATA ENTRY'!$M9,""))) | Y9: =IF($X9="","",IFERROR(365/$X9,"")) | Z9: =IF($B9="","",IF($X9="","Not entered",IF($Y9<=60,"Strong",IF($Y9<=90,"Adequate",IF($Y9<=120,"Caution","High-risk"))))) | AA9: =IF(OR($B9="",'DATA ENTRY'!$G9="",'DATA ENTRY'!$Q9=""),"",IFERROR('DATA ENTRY'!$G9/'DATA ENTRY'!$Q9,"")) | AB9: =IF($B9="","",IF($AA9="","Not entered",IF($AA9>=1.5,"Strong",IF($AA9>=1,"Adequate",IF($AA9>=0.5,"Caution","High-risk"))))) | AC9: =IF(OR($B9="",'DATA ENTRY'!$K9="",'DATA ENTRY'!$R9=""),"",'DATA ENTRY'!$K9-'DATA ENTRY'!$R9) | AD9: =IF($B9="","",IF($AC9="","Not entered",IF($AC9<0,"High-risk",IF($AC9=0,"Caution",IF('DATA ENTRY'!$L9="","Adequate",IFERROR(IF('DATA ENTRY'!$L9/'DATA ENTRY'!$R9>=0.25,"Strong","Adequate"),"Adequate")))))) | AE9: =IF($B9="","",IF(OR('DATA ENTRY'!$W9="",'DATA ENTRY'!$W9=0),"N/A",IF('DATA ENTRY'!$V9="","",IFERROR('DATA ENTRY'!$V9/'DATA ENTRY'!$W9,"")))) | AF9: =IF($B9="","",IF($AE9="N/A","Not applicable",IF($AE9="","Not entered",IF($AE9>=4,"Strong",IF($AE9>=2.5,"Adequate",IF($AE9>=1.5,"Caution","High-risk")))))) | AG9: =IF($B9="","",IFERROR(ROUND((COUNTIF($I9:$AF9,"Strong")*4+COUNTIF($I9:$AF9,"Adequate")*3+COUNTIF($I9:$AF9,"Caution")*2+COUNTIF($I9:$AF9,"High-risk")*1)/(COUNTIF($I9:$AF9,"Strong")+COUNTIF($I9:$AF9,"Adequate")+COUNTIF($I9:$AF9,"Caution")+COUNTIF($I9:$AF9,"High-risk")),2),"")) | AH9: =IF($B9="","",IF(AND(ISNUMBER('DATA ENTRY'!$U9),'DATA ENTRY'!$U9<=0),"Financially stretched",IF($AG9="","Insufficient data",IF(AND(ISNUMBER('DATA ENTRY'!$J9),'DATA ENTRY'!$J9<0),IF($AG9>=2,"Adequate with caution","Financially stretched"),IF($AG9>=3.5,"Financially strong",IF($AG9>=2.75,"Financially adequate",IF($AG9>=2,"Adequate with caution","Financially stretched"))))))) | AI9: =IF($B9="","",IF(AND(ISNUMBER('DATA ENTRY'!$U9),'DATA ENTRY'!$U9<=0),"Negative equity — possible insolvency",IF(AND(ISNUMBER('DATA ENTRY'!$J9),'DATA ENTRY'!$J9<0),"Loss position",IF(AND(ISNUMBER($P9),$P9<1),"Current liabilities exceed current assets",IF(AND(ISNUMBER($T9),$T9>2),"High leverage",IF(AND(ISNUMBER($Y9),$Y9>120),"Slow receivables collection",IF(AND(ISNUMBER($AC9),$AC9<0),"Negative working capital",IF(OR('DATA ENTRY'!$E9="Unaudited",'DATA ENTRY'!$E9="Banker Letter Only",'DATA ENTRY'!$E9="Management Accounts"),"Statement status limits weight on ratios","No major red flag from entered ratios"))))))))
A10: =IF('DATA ENTRY'!$B10<>"",'DATA ENTRY'!$A10,"") | B10: =IF('DATA ENTRY'!$B10<>"",'DATA ENTRY'!$B10,"") | C10: =IF('DATA ENTRY'!$B10<>"",'DATA ENTRY'!$C10,"") | D10: =IF('DATA ENTRY'!$B10<>"",'DATA ENTRY'!$D10,"") | E10: =IF('DATA ENTRY'!$B10<>"",'DATA ENTRY'!$E10,"") | F10: =IF($B10="","",IF('DATA ENTRY'!$Y10="Yes","Checked",IF('DATA ENTRY'!$Y10="No","Needs check","Not marked"))) | G10: =IF($B10="","",IF('DATA ENTRY'!$I10<>"",'DATA ENTRY'!$I10,IF(AND('DATA ENTRY'!$G10<>"",'DATA ENTRY'!$H10<>""),'DATA ENTRY'!$G10-'DATA ENTRY'!$H10,""))) | H10: =IF(OR($B10="",$G10="",'DATA ENTRY'!$G10=""),"",IFERROR($G10/'DATA ENTRY'!$G10,"")) | I10: =IF($B10="","",IF($H10="","Not entered",IF($H10>=0.25,"Strong",IF($H10>=0.15,"Adequate",IF($H10>=0.05,"Caution","High-risk"))))) | J10: =IF(OR($B10="",'DATA ENTRY'!$J10="",'DATA ENTRY'!$G10=""),"",IFERROR('DATA ENTRY'!$J10/'DATA ENTRY'!$G10,"")) | K10: =IF($B10="","",IF($J10="","Not entered",IF($J10>=0.08,"Strong",IF($J10>=0.03,"Adequate",IF($J10>=0,"Caution","High-risk"))))) | L10: =IF(OR($B10="",'DATA ENTRY'!$J10="",'DATA ENTRY'!$Q10=""),"",IFERROR('DATA ENTRY'!$J10/'DATA ENTRY'!$Q10,"")) | M10: =IF($B10="","",IF($L10="","Not entered",IF($L10>=0.1,"Strong",IF($L10>=0.05,"Adequate",IF($L10>=0,"Caution","High-risk"))))) | N10: =IF(OR($B10="",'DATA ENTRY'!$J10="",'DATA ENTRY'!$U10="",'DATA ENTRY'!$U10<=0),"",IFERROR('DATA ENTRY'!$J10/'DATA ENTRY'!$U10,"")) | O10: =IF($B10="","",IF(OR('DATA ENTRY'!$J10="",'DATA ENTRY'!$U10=""),"Not entered",IF('DATA ENTRY'!$U10<=0,"High-risk",IF($N10>=0.15,"Strong",IF($N10>=0.08,"Adequate",IF($N10>=0,"Caution","High-risk")))))) | P10: =IF(OR($B10="",'DATA ENTRY'!$K10="",'DATA ENTRY'!$R10=""),"",IFERROR('DATA ENTRY'!$K10/'DATA ENTRY'!$R10,"")) | Q10: =IF($B10="","",IF($P10="","Not entered",IF($P10>=1.5,"Strong",IF($P10>=1.2,"Adequate",IF($P10>=1,"Caution","High-risk"))))) | R10: =IF(OR($B10="",'DATA ENTRY'!$K10="",'DATA ENTRY'!$R10=""),"",IFERROR(('DATA ENTRY'!$K10-IF('DATA ENTRY'!$O10="",0,'DATA ENTRY'!$O10))/'DATA ENTRY'!$R10,"")) | S10: =IF($B10="","",IF($R10="","Not entered",IF($R10>=1,"Strong",IF($R10>=0.8,"Adequate",IF($R10>=0.6,"Caution","High-risk"))))) | T10: =IF(OR($B10="",'DATA ENTRY'!$T10="",'DATA ENTRY'!$U10="",'DATA ENTRY'!$U10<=0),"",IFERROR('DATA ENTRY'!$T10/'DATA ENTRY'!$U10,"")) | U10: =IF($B10="","",IF(OR('DATA ENTRY'!$T10="",'DATA ENTRY'!$U10=""),"Not entered",IF('DATA ENTRY'!$U10<=0,"High-risk",IF($T10<=1,"Strong",IF($T10<=1.5,"Adequate",IF($T10<=2,"Caution","High-risk")))))) | V10: =IF(OR($B10="",'DATA ENTRY'!$U10="",'DATA ENTRY'!$Q10=""),"",IFERROR('DATA ENTRY'!$U10/'DATA ENTRY'!$Q10,"")) | W10: =IF($B10="","",IF($V10="","Not entered",IF($V10>=0.5,"Strong",IF($V10>=0.3,"Adequate",IF($V10>=0.2,"Caution","High-risk"))))) | X10: =IF(OR($B10="",'DATA ENTRY'!$G10="",'DATA ENTRY'!$M10=""),"",IF('DATA ENTRY'!$N10<>"",'DATA ENTRY'!$G10/AVERAGE('DATA ENTRY'!$M10,'DATA ENTRY'!$N10),IFERROR('DATA ENTRY'!$G10/'DATA ENTRY'!$M10,""))) | Y10: =IF($X10="","",IFERROR(365/$X10,"")) | Z10: =IF($B10="","",IF($X10="","Not entered",IF($Y10<=60,"Strong",IF($Y10<=90,"Adequate",IF($Y10<=120,"Caution","High-risk"))))) | AA10: =IF(OR($B10="",'DATA ENTRY'!$G10="",'DATA ENTRY'!$Q10=""),"",IFERROR('DATA ENTRY'!$G10/'DATA ENTRY'!$Q10,"")) | AB10: =IF($B10="","",IF($AA10="","Not entered",IF($AA10>=1.5,"Strong",IF($AA10>=1,"Adequate",IF($AA10>=0.5,"Caution","High-risk"))))) | AC10: =IF(OR($B10="",'DATA ENTRY'!$K10="",'DATA ENTRY'!$R10=""),"",'DATA ENTRY'!$K10-'DATA ENTRY'!$R10) | AD10: =IF($B10="","",IF($AC10="","Not entered",IF($AC10<0,"High-risk",IF($AC10=0,"Caution",IF('DATA ENTRY'!$L10="","Adequate",IFERROR(IF('DATA ENTRY'!$L10/'DATA ENTRY'!$R10>=0.25,"Strong","Adequate"),"Adequate")))))) | AE10: =IF($B10="","",IF(OR('DATA ENTRY'!$W10="",'DATA ENTRY'!$W10=0),"N/A",IF('DATA ENTRY'!$V10="","",IFERROR('DATA ENTRY'!$V10/'DATA ENTRY'!$W10,"")))) | AF10: =IF($B10="","",IF($AE10="N/A","Not applicable",IF($AE10="","Not entered",IF($AE10>=4,"Strong",IF($AE10>=2.5,"Adequate",IF($AE10>=1.5,"Caution","High-risk")))))) | AG10: =IF($B10="","",IFERROR(ROUND((COUNTIF($I10:$AF10,"Strong")*4+COUNTIF($I10:$AF10,"Adequate")*3+COUNTIF($I10:$AF10,"Caution")*2+COUNTIF($I10:$AF10,"High-risk")*1)/(COUNTIF($I10:$AF10,"Strong")+COUNTIF($I10:$AF10,"Adequate")+COUNTIF($I10:$AF10,"Caution")+COUNTIF($I10:$AF10,"High-risk")),2),"")) | AH10: =IF($B10="","",IF(AND(ISNUMBER('DATA ENTRY'!$U10),'DATA ENTRY'!$U10<=0),"Financially stretched",IF($AG10="","Insufficient data",IF(AND(ISNUMBER('DATA ENTRY'!$J10),'DATA ENTRY'!$J10<0),IF($AG10>=2,"Adequate with caution","Financially stretched"),IF($AG10>=3.5,"Financially strong",IF($AG10>=2.75,"Financially adequate",IF($AG10>=2,"Adequate with caution","Financially stretched"))))))) | AI10: =IF($B10="","",IF(AND(ISNUMBER('DATA ENTRY'!$U10),'DATA ENTRY'!$U10<=0),"Negative equity — possible insolvency",IF(AND(ISNUMBER('DATA ENTRY'!$J10),'DATA ENTRY'!$J10<0),"Loss position",IF(AND(ISNUMBER($P10),$P10<1),"Current liabilities exceed current assets",IF(AND(ISNUMBER($T10),$T10>2),"High leverage",IF(AND(ISNUMBER($Y10),$Y10>120),"Slow receivables collection",IF(AND(ISNUMBER($AC10),$AC10<0),"Negative working capital",IF(OR('DATA ENTRY'!$E10="Unaudited",'DATA ENTRY'!$E10="Banker Letter Only",'DATA ENTRY'!$E10="Management Accounts"),"Statement status limits weight on ratios","No major red flag from entered ratios"))))))))
A11: =IF('DATA ENTRY'!$B11<>"",'DATA ENTRY'!$A11,"") | B11: =IF('DATA ENTRY'!$B11<>"",'DATA ENTRY'!$B11,"") | C11: =IF('DATA ENTRY'!$B11<>"",'DATA ENTRY'!$C11,"") | D11: =IF('DATA ENTRY'!$B11<>"",'DATA ENTRY'!$D11,"") | E11: =IF('DATA ENTRY'!$B11<>"",'DATA ENTRY'!$E11,"") | F11: =IF($B11="","",IF('DATA ENTRY'!$Y11="Yes","Checked",IF('DATA ENTRY'!$Y11="No","Needs check","Not marked"))) | G11: =IF($B11="","",IF('DATA ENTRY'!$I11<>"",'DATA ENTRY'!$I11,IF(AND('DATA ENTRY'!$G11<>"",'DATA ENTRY'!$H11<>""),'DATA ENTRY'!$G11-'DATA ENTRY'!$H11,""))) | H11: =IF(OR($B11="",$G11="",'DATA ENTRY'!$G11=""),"",IFERROR($G11/'DATA ENTRY'!$G11,"")) | I11: =IF($B11="","",IF($H11="","Not entered",IF($H11>=0.25,"Strong",IF($H11>=0.15,"Adequate",IF($H11>=0.05,"Caution","High-risk"))))) | J11: =IF(OR($B11="",'DATA ENTRY'!$J11="",'DATA ENTRY'!$G11=""),"",IFERROR('DATA ENTRY'!$J11/'DATA ENTRY'!$G11,"")) | K11: =IF($B11="","",IF($J11="","Not entered",IF($J11>=0.08,"Strong",IF($J11>=0.03,"Adequate",IF($J11>=0,"Caution","High-risk"))))) | L11: =IF(OR($B11="",'DATA ENTRY'!$J11="",'DATA ENTRY'!$Q11=""),"",IFERROR('DATA ENTRY'!$J11/'DATA ENTRY'!$Q11,"")) | M11: =IF($B11="","",IF($L11="","Not entered",IF($L11>=0.1,"Strong",IF($L11>=0.05,"Adequate",IF($L11>=0,"Caution","High-risk"))))) | N11: =IF(OR($B11="",'DATA ENTRY'!$J11="",'DATA ENTRY'!$U11="",'DATA ENTRY'!$U11<=0),"",IFERROR('DATA ENTRY'!$J11/'DATA ENTRY'!$U11,"")) | O11: =IF($B11="","",IF(OR('DATA ENTRY'!$J11="",'DATA ENTRY'!$U11=""),"Not entered",IF('DATA ENTRY'!$U11<=0,"High-risk",IF($N11>=0.15,"Strong",IF($N11>=0.08,"Adequate",IF($N11>=0,"Caution","High-risk")))))) | P11: =IF(OR($B11="",'DATA ENTRY'!$K11="",'DATA ENTRY'!$R11=""),"",IFERROR('DATA ENTRY'!$K11/'DATA ENTRY'!$R11,"")) | Q11: =IF($B11="","",IF($P11="","Not entered",IF($P11>=1.5,"Strong",IF($P11>=1.2,"Adequate",IF($P11>=1,"Caution","High-risk"))))) | R11: =IF(OR($B11="",'DATA ENTRY'!$K11="",'DATA ENTRY'!$R11=""),"",IFERROR(('DATA ENTRY'!$K11-IF('DATA ENTRY'!$O11="",0,'DATA ENTRY'!$O11))/'DATA ENTRY'!$R11,"")) | S11: =IF($B11="","",IF($R11="","Not entered",IF($R11>=1,"Strong",IF($R11>=0.8,"Adequate",IF($R11>=0.6,"Caution","High-risk"))))) | T11: =IF(OR($B11="",'DATA ENTRY'!$T11="",'DATA ENTRY'!$U11="",'DATA ENTRY'!$U11<=0),"",IFERROR('DATA ENTRY'!$T11/'DATA ENTRY'!$U11,"")) | U11: =IF($B11="","",IF(OR('DATA ENTRY'!$T11="",'DATA ENTRY'!$U11=""),"Not entered",IF('DATA ENTRY'!$U11<=0,"High-risk",IF($T11<=1,"Strong",IF($T11<=1.5,"Adequate",IF($T11<=2,"Caution","High-risk")))))) | V11: =IF(OR($B11="",'DATA ENTRY'!$U11="",'DATA ENTRY'!$Q11=""),"",IFERROR('DATA ENTRY'!$U11/'DATA ENTRY'!$Q11,"")) | W11: =IF($B11="","",IF($V11="","Not entered",IF($V11>=0.5,"Strong",IF($V11>=0.3,"Adequate",IF($V11>=0.2,"Caution","High-risk"))))) | X11: =IF(OR($B11="",'DATA ENTRY'!$G11="",'DATA ENTRY'!$M11=""),"",IF('DATA ENTRY'!$N11<>"",'DATA ENTRY'!$G11/AVERAGE('DATA ENTRY'!$M11,'DATA ENTRY'!$N11),IFERROR('DATA ENTRY'!$G11/'DATA ENTRY'!$M11,""))) | Y11: =IF($X11="","",IFERROR(365/$X11,"")) | Z11: =IF($B11="","",IF($X11="","Not entered",IF($Y11<=60,"Strong",IF($Y11<=90,"Adequate",IF($Y11<=120,"Caution","High-risk"))))) | AA11: =IF(OR($B11="",'DATA ENTRY'!$G11="",'DATA ENTRY'!$Q11=""),"",IFERROR('DATA ENTRY'!$G11/'DATA ENTRY'!$Q11,"")) | AB11: =IF($B11="","",IF($AA11="","Not entered",IF($AA11>=1.5,"Strong",IF($AA11>=1,"Adequate",IF($AA11>=0.5,"Caution","High-risk"))))) | AC11: =IF(OR($B11="",'DATA ENTRY'!$K11="",'DATA ENTRY'!$R11=""),"",'DATA ENTRY'!$K11-'DATA ENTRY'!$R11) | AD11: =IF($B11="","",IF($AC11="","Not entered",IF($AC11<0,"High-risk",IF($AC11=0,"Caution",IF('DATA ENTRY'!$L11="","Adequate",IFERROR(IF('DATA ENTRY'!$L11/'DATA ENTRY'!$R11>=0.25,"Strong","Adequate"),"Adequate")))))) | AE11: =IF($B11="","",IF(OR('DATA ENTRY'!$W11="",'DATA ENTRY'!$W11=0),"N/A",IF('DATA ENTRY'!$V11="","",IFERROR('DATA ENTRY'!$V11/'DATA ENTRY'!$W11,"")))) | AF11: =IF($B11="","",IF($AE11="N/A","Not applicable",IF($AE11="","Not entered",IF($AE11>=4,"Strong",IF($AE11>=2.5,"Adequate",IF($AE11>=1.5,"Caution","High-risk")))))) | AG11: =IF($B11="","",IFERROR(ROUND((COUNTIF($I11:$AF11,"Strong")*4+COUNTIF($I11:$AF11,"Adequate")*3+COUNTIF($I11:$AF11,"Caution")*2+COUNTIF($I11:$AF11,"High-risk")*1)/(COUNTIF($I11:$AF11,"Strong")+COUNTIF($I11:$AF11,"Adequate")+COUNTIF($I11:$AF11,"Caution")+COUNTIF($I11:$AF11,"High-risk")),2),"")) | AH11: =IF($B11="","",IF(AND(ISNUMBER('DATA ENTRY'!$U11),'DATA ENTRY'!$U11<=0),"Financially stretched",IF($AG11="","Insufficient data",IF(AND(ISNUMBER('DATA ENTRY'!$J11),'DATA ENTRY'!$J11<0),IF($AG11>=2,"Adequate with caution","Financially stretched"),IF($AG11>=3.5,"Financially strong",IF($AG11>=2.75,"Financially adequate",IF($AG11>=2,"Adequate with caution","Financially stretched"))))))) | AI11: =IF($B11="","",IF(AND(ISNUMBER('DATA ENTRY'!$U11),'DATA ENTRY'!$U11<=0),"Negative equity — possible insolvency",IF(AND(ISNUMBER('DATA ENTRY'!$J11),'DATA ENTRY'!$J11<0),"Loss position",IF(AND(ISNUMBER($P11),$P11<1),"Current liabilities exceed current assets",IF(AND(ISNUMBER($T11),$T11>2),"High leverage",IF(AND(ISNUMBER($Y11),$Y11>120),"Slow receivables collection",IF(AND(ISNUMBER($AC11),$AC11<0),"Negative working capital",IF(OR('DATA ENTRY'!$E11="Unaudited",'DATA ENTRY'!$E11="Banker Letter Only",'DATA ENTRY'!$E11="Management Accounts"),"Statement status limits weight on ratios","No major red flag from entered ratios"))))))))
A12: =IF('DATA ENTRY'!$B12<>"",'DATA ENTRY'!$A12,"") | B12: =IF('DATA ENTRY'!$B12<>"",'DATA ENTRY'!$B12,"") | C12: =IF('DATA ENTRY'!$B12<>"",'DATA ENTRY'!$C12,"") | D12: =IF('DATA ENTRY'!$B12<>"",'DATA ENTRY'!$D12,"") | E12: =IF('DATA ENTRY'!$B12<>"",'DATA ENTRY'!$E12,"") | F12: =IF($B12="","",IF('DATA ENTRY'!$Y12="Yes","Checked",IF('DATA ENTRY'!$Y12="No","Needs check","Not marked"))) | G12: =IF($B12="","",IF('DATA ENTRY'!$I12<>"",'DATA ENTRY'!$I12,IF(AND('DATA ENTRY'!$G12<>"",'DATA ENTRY'!$H12<>""),'DATA ENTRY'!$G12-'DATA ENTRY'!$H12,""))) | H12: =IF(OR($B12="",$G12="",'DATA ENTRY'!$G12=""),"",IFERROR($G12/'DATA ENTRY'!$G12,"")) | I12: =IF($B12="","",IF($H12="","Not entered",IF($H12>=0.25,"Strong",IF($H12>=0.15,"Adequate",IF($H12>=0.05,"Caution","High-risk"))))) | J12: =IF(OR($B12="",'DATA ENTRY'!$J12="",'DATA ENTRY'!$G12=""),"",IFERROR('DATA ENTRY'!$J12/'DATA ENTRY'!$G12,"")) | K12: =IF($B12="","",IF($J12="","Not entered",IF($J12>=0.08,"Strong",IF($J12>=0.03,"Adequate",IF($J12>=0,"Caution","High-risk"))))) | L12: =IF(OR($B12="",'DATA ENTRY'!$J12="",'DATA ENTRY'!$Q12=""),"",IFERROR('DATA ENTRY'!$J12/'DATA ENTRY'!$Q12,"")) | M12: =IF($B12="","",IF($L12="","Not entered",IF($L12>=0.1,"Strong",IF($L12>=0.05,"Adequate",IF($L12>=0,"Caution","High-risk"))))) | N12: =IF(OR($B12="",'DATA ENTRY'!$J12="",'DATA ENTRY'!$U12="",'DATA ENTRY'!$U12<=0),"",IFERROR('DATA ENTRY'!$J12/'DATA ENTRY'!$U12,"")) | O12: =IF($B12="","",IF(OR('DATA ENTRY'!$J12="",'DATA ENTRY'!$U12=""),"Not entered",IF('DATA ENTRY'!$U12<=0,"High-risk",IF($N12>=0.15,"Strong",IF($N12>=0.08,"Adequate",IF($N12>=0,"Caution","High-risk")))))) | P12: =IF(OR($B12="",'DATA ENTRY'!$K12="",'DATA ENTRY'!$R12=""),"",IFERROR('DATA ENTRY'!$K12/'DATA ENTRY'!$R12,"")) | Q12: =IF($B12="","",IF($P12="","Not entered",IF($P12>=1.5,"Strong",IF($P12>=1.2,"Adequate",IF($P12>=1,"Caution","High-risk"))))) | R12: =IF(OR($B12="",'DATA ENTRY'!$K12="",'DATA ENTRY'!$R12=""),"",IFERROR(('DATA ENTRY'!$K12-IF('DATA ENTRY'!$O12="",0,'DATA ENTRY'!$O12))/'DATA ENTRY'!$R12,"")) | S12: =IF($B12="","",IF($R12="","Not entered",IF($R12>=1,"Strong",IF($R12>=0.8,"Adequate",IF($R12>=0.6,"Caution","High-risk"))))) | T12: =IF(OR($B12="",'DATA ENTRY'!$T12="",'DATA ENTRY'!$U12="",'DATA ENTRY'!$U12<=0),"",IFERROR('DATA ENTRY'!$T12/'DATA ENTRY'!$U12,"")) | U12: =IF($B12="","",IF(OR('DATA ENTRY'!$T12="",'DATA ENTRY'!$U12=""),"Not entered",IF('DATA ENTRY'!$U12<=0,"High-risk",IF($T12<=1,"Strong",IF($T12<=1.5,"Adequate",IF($T12<=2,"Caution","High-risk")))))) | V12: =IF(OR($B12="",'DATA ENTRY'!$U12="",'DATA ENTRY'!$Q12=""),"",IFERROR('DATA ENTRY'!$U12/'DATA ENTRY'!$Q12,"")) | W12: =IF($B12="","",IF($V12="","Not entered",IF($V12>=0.5,"Strong",IF($V12>=0.3,"Adequate",IF($V12>=0.2,"Caution","High-risk"))))) | X12: =IF(OR($B12="",'DATA ENTRY'!$G12="",'DATA ENTRY'!$M12=""),"",IF('DATA ENTRY'!$N12<>"",'DATA ENTRY'!$G12/AVERAGE('DATA ENTRY'!$M12,'DATA ENTRY'!$N12),IFERROR('DATA ENTRY'!$G12/'DATA ENTRY'!$M12,""))) | Y12: =IF($X12="","",IFERROR(365/$X12,"")) | Z12: =IF($B12="","",IF($X12="","Not entered",IF($Y12<=60,"Strong",IF($Y12<=90,"Adequate",IF($Y12<=120,"Caution","High-risk"))))) | AA12: =IF(OR($B12="",'DATA ENTRY'!$G12="",'DATA ENTRY'!$Q12=""),"",IFERROR('DATA ENTRY'!$G12/'DATA ENTRY'!$Q12,"")) | AB12: =IF($B12="","",IF($AA12="","Not entered",IF($AA12>=1.5,"Strong",IF($AA12>=1,"Adequate",IF($AA12>=0.5,"Caution","High-risk"))))) | AC12: =IF(OR($B12="",'DATA ENTRY'!$K12="",'DATA ENTRY'!$R12=""),"",'DATA ENTRY'!$K12-'DATA ENTRY'!$R12) | AD12: =IF($B12="","",IF($AC12="","Not entered",IF($AC12<0,"High-risk",IF($AC12=0,"Caution",IF('DATA ENTRY'!$L12="","Adequate",IFERROR(IF('DATA ENTRY'!$L12/'DATA ENTRY'!$R12>=0.25,"Strong","Adequate"),"Adequate")))))) | AE12: =IF($B12="","",IF(OR('DATA ENTRY'!$W12="",'DATA ENTRY'!$W12=0),"N/A",IF('DATA ENTRY'!$V12="","",IFERROR('DATA ENTRY'!$V12/'DATA ENTRY'!$W12,"")))) | AF12: =IF($B12="","",IF($AE12="N/A","Not applicable",IF($AE12="","Not entered",IF($AE12>=4,"Strong",IF($AE12>=2.5,"Adequate",IF($AE12>=1.5,"Caution","High-risk")))))) | AG12: =IF($B12="","",IFERROR(ROUND((COUNTIF($I12:$AF12,"Strong")*4+COUNTIF($I12:$AF12,"Adequate")*3+COUNTIF($I12:$AF12,"Caution")*2+COUNTIF($I12:$AF12,"High-risk")*1)/(COUNTIF($I12:$AF12,"Strong")+COUNTIF($I12:$AF12,"Adequate")+COUNTIF($I12:$AF12,"Caution")+COUNTIF($I12:$AF12,"High-risk")),2),"")) | AH12: =IF($B12="","",IF(AND(ISNUMBER('DATA ENTRY'!$U12),'DATA ENTRY'!$U12<=0),"Financially stretched",IF($AG12="","Insufficient data",IF(AND(ISNUMBER('DATA ENTRY'!$J12),'DATA ENTRY'!$J12<0),IF($AG12>=2,"Adequate with caution","Financially stretched"),IF($AG12>=3.5,"Financially strong",IF($AG12>=2.75,"Financially adequate",IF($AG12>=2,"Adequate with caution","Financially stretched"))))))) | AI12: =IF($B12="","",IF(AND(ISNUMBER('DATA ENTRY'!$U12),'DATA ENTRY'!$U12<=0),"Negative equity — possible insolvency",IF(AND(ISNUMBER('DATA ENTRY'!$J12),'DATA ENTRY'!$J12<0),"Loss position",IF(AND(ISNUMBER($P12),$P12<1),"Current liabilities exceed current assets",IF(AND(ISNUMBER($T12),$T12>2),"High leverage",IF(AND(ISNUMBER($Y12),$Y12>120),"Slow receivables collection",IF(AND(ISNUMBER($AC12),$AC12<0),"Negative working capital",IF(OR('DATA ENTRY'!$E12="Unaudited",'DATA ENTRY'!$E12="Banker Letter Only",'DATA ENTRY'!$E12="Management Accounts"),"Statement status limits weight on ratios","No major red flag from entered ratios"))))))))
A13: =IF('DATA ENTRY'!$B13<>"",'DATA ENTRY'!$A13,"") | B13: =IF('DATA ENTRY'!$B13<>"",'DATA ENTRY'!$B13,"") | C13: =IF('DATA ENTRY'!$B13<>"",'DATA ENTRY'!$C13,"") | D13: =IF('DATA ENTRY'!$B13<>"",'DATA ENTRY'!$D13,"") | E13: =IF('DATA ENTRY'!$B13<>"",'DATA ENTRY'!$E13,"") | F13: =IF($B13="","",IF('DATA ENTRY'!$Y13="Yes","Checked",IF('DATA ENTRY'!$Y13="No","Needs check","Not marked"))) | G13: =IF($B13="","",IF('DATA ENTRY'!$I13<>"",'DATA ENTRY'!$I13,IF(AND('DATA ENTRY'!$G13<>"",'DATA ENTRY'!$H13<>""),'DATA ENTRY'!$G13-'DATA ENTRY'!$H13,""))) | H13: =IF(OR($B13="",$G13="",'DATA ENTRY'!$G13=""),"",IFERROR($G13/'DATA ENTRY'!$G13,"")) | I13: =IF($B13="","",IF($H13="","Not entered",IF($H13>=0.25,"Strong",IF($H13>=0.15,"Adequate",IF($H13>=0.05,"Caution","High-risk"))))) | J13: =IF(OR($B13="",'DATA ENTRY'!$J13="",'DATA ENTRY'!$G13=""),"",IFERROR('DATA ENTRY'!$J13/'DATA ENTRY'!$G13,"")) | K13: =IF($B13="","",IF($J13="","Not entered",IF($J13>=0.08,"Strong",IF($J13>=0.03,"Adequate",IF($J13>=0,"Caution","High-risk"))))) | L13: =IF(OR($B13="",'DATA ENTRY'!$J13="",'DATA ENTRY'!$Q13=""),"",IFERROR('DATA ENTRY'!$J13/'DATA ENTRY'!$Q13,"")) | M13: =IF($B13="","",IF($L13="","Not entered",IF($L13>=0.1,"Strong",IF($L13>=0.05,"Adequate",IF($L13>=0,"Caution","High-risk"))))) | N13: =IF(OR($B13="",'DATA ENTRY'!$J13="",'DATA ENTRY'!$U13="",'DATA ENTRY'!$U13<=0),"",IFERROR('DATA ENTRY'!$J13/'DATA ENTRY'!$U13,"")) | O13: =IF($B13="","",IF(OR('DATA ENTRY'!$J13="",'DATA ENTRY'!$U13=""),"Not entered",IF('DATA ENTRY'!$U13<=0,"High-risk",IF($N13>=0.15,"Strong",IF($N13>=0.08,"Adequate",IF($N13>=0,"Caution","High-risk")))))) | P13: =IF(OR($B13="",'DATA ENTRY'!$K13="",'DATA ENTRY'!$R13=""),"",IFERROR('DATA ENTRY'!$K13/'DATA ENTRY'!$R13,"")) | Q13: =IF($B13="","",IF($P13="","Not entered",IF($P13>=1.5,"Strong",IF($P13>=1.2,"Adequate",IF($P13>=1,"Caution","High-risk"))))) | R13: =IF(OR($B13="",'DATA ENTRY'!$K13="",'DATA ENTRY'!$R13=""),"",IFERROR(('DATA ENTRY'!$K13-IF('DATA ENTRY'!$O13="",0,'DATA ENTRY'!$O13))/'DATA ENTRY'!$R13,"")) | S13: =IF($B13="","",IF($R13="","Not entered",IF($R13>=1,"Strong",IF($R13>=0.8,"Adequate",IF($R13>=0.6,"Caution","High-risk"))))) | T13: =IF(OR($B13="",'DATA ENTRY'!$T13="",'DATA ENTRY'!$U13="",'DATA ENTRY'!$U13<=0),"",IFERROR('DATA ENTRY'!$T13/'DATA ENTRY'!$U13,"")) | U13: =IF($B13="","",IF(OR('DATA ENTRY'!$T13="",'DATA ENTRY'!$U13=""),"Not entered",IF('DATA ENTRY'!$U13<=0,"High-risk",IF($T13<=1,"Strong",IF($T13<=1.5,"Adequate",IF($T13<=2,"Caution","High-risk")))))) | V13: =IF(OR($B13="",'DATA ENTRY'!$U13="",'DATA ENTRY'!$Q13=""),"",IFERROR('DATA ENTRY'!$U13/'DATA ENTRY'!$Q13,"")) | W13: =IF($B13="","",IF($V13="","Not entered",IF($V13>=0.5,"Strong",IF($V13>=0.3,"Adequate",IF($V13>=0.2,"Caution","High-risk"))))) | X13: =IF(OR($B13="",'DATA ENTRY'!$G13="",'DATA ENTRY'!$M13=""),"",IF('DATA ENTRY'!$N13<>"",'DATA ENTRY'!$G13/AVERAGE('DATA ENTRY'!$M13,'DATA ENTRY'!$N13),IFERROR('DATA ENTRY'!$G13/'DATA ENTRY'!$M13,""))) | Y13: =IF($X13="","",IFERROR(365/$X13,"")) | Z13: =IF($B13="","",IF($X13="","Not entered",IF($Y13<=60,"Strong",IF($Y13<=90,"Adequate",IF($Y13<=120,"Caution","High-risk"))))) | AA13: =IF(OR($B13="",'DATA ENTRY'!$G13="",'DATA ENTRY'!$Q13=""),"",IFERROR('DATA ENTRY'!$G13/'DATA ENTRY'!$Q13,"")) | AB13: =IF($B13="","",IF($AA13="","Not entered",IF($AA13>=1.5,"Strong",IF($AA13>=1,"Adequate",IF($AA13>=0.5,"Caution","High-risk"))))) | AC13: =IF(OR($B13="",'DATA ENTRY'!$K13="",'DATA ENTRY'!$R13=""),"",'DATA ENTRY'!$K13-'DATA ENTRY'!$R13) | AD13: =IF($B13="","",IF($AC13="","Not entered",IF($AC13<0,"High-risk",IF($AC13=0,"Caution",IF('DATA ENTRY'!$L13="","Adequate",IFERROR(IF('DATA ENTRY'!$L13/'DATA ENTRY'!$R13>=0.25,"Strong","Adequate"),"Adequate")))))) | AE13: =IF($B13="","",IF(OR('DATA ENTRY'!$W13="",'DATA ENTRY'!$W13=0),"N/A",IF('DATA ENTRY'!$V13="","",IFERROR('DATA ENTRY'!$V13/'DATA ENTRY'!$W13,"")))) | AF13: =IF($B13="","",IF($AE13="N/A","Not applicable",IF($AE13="","Not entered",IF($AE13>=4,"Strong",IF($AE13>=2.5,"Adequate",IF($AE13>=1.5,"Caution","High-risk")))))) | AG13: =IF($B13="","",IFERROR(ROUND((COUNTIF($I13:$AF13,"Strong")*4+COUNTIF($I13:$AF13,"Adequate")*3+COUNTIF($I13:$AF13,"Caution")*2+COUNTIF($I13:$AF13,"High-risk")*1)/(COUNTIF($I13:$AF13,"Strong")+COUNTIF($I13:$AF13,"Adequate")+COUNTIF($I13:$AF13,"Caution")+COUNTIF($I13:$AF13,"High-risk")),2),"")) | AH13: =IF($B13="","",IF(AND(ISNUMBER('DATA ENTRY'!$U13),'DATA ENTRY'!$U13<=0),"Financially stretched",IF($AG13="","Insufficient data",IF(AND(ISNUMBER('DATA ENTRY'!$J13),'DATA ENTRY'!$J13<0),IF($AG13>=2,"Adequate with caution","Financially stretched"),IF($AG13>=3.5,"Financially strong",IF($AG13>=2.75,"Financially adequate",IF($AG13>=2,"Adequate with caution","Financially stretched"))))))) | AI13: =IF($B13="","",IF(AND(ISNUMBER('DATA ENTRY'!$U13),'DATA ENTRY'!$U13<=0),"Negative equity — possible insolvency",IF(AND(ISNUMBER('DATA ENTRY'!$J13),'DATA ENTRY'!$J13<0),"Loss position",IF(AND(ISNUMBER($P13),$P13<1),"Current liabilities exceed current assets",IF(AND(ISNUMBER($T13),$T13>2),"High leverage",IF(AND(ISNUMBER($Y13),$Y13>120),"Slow receivables collection",IF(AND(ISNUMBER($AC13),$AC13<0),"Negative working capital",IF(OR('DATA ENTRY'!$E13="Unaudited",'DATA ENTRY'!$E13="Banker Letter Only",'DATA ENTRY'!$E13="Management Accounts"),"Statement status limits weight on ratios","No major red flag from entered ratios"))))))))
A14: =IF('DATA ENTRY'!$B14<>"",'DATA ENTRY'!$A14,"") | B14: =IF('DATA ENTRY'!$B14<>"",'DATA ENTRY'!$B14,"") | C14: =IF('DATA ENTRY'!$B14<>"",'DATA ENTRY'!$C14,"") | D14: =IF('DATA ENTRY'!$B14<>"",'DATA ENTRY'!$D14,"") | E14: =IF('DATA ENTRY'!$B14<>"",'DATA ENTRY'!$E14,"") | F14: =IF($B14="","",IF('DATA ENTRY'!$Y14="Yes","Checked",IF('DATA ENTRY'!$Y14="No","Needs check","Not marked"))) | G14: =IF($B14="","",IF('DATA ENTRY'!$I14<>"",'DATA ENTRY'!$I14,IF(AND('DATA ENTRY'!$G14<>"",'DATA ENTRY'!$H14<>""),'DATA ENTRY'!$G14-'DATA ENTRY'!$H14,""))) | H14: =IF(OR($B14="",$G14="",'DATA ENTRY'!$G14=""),"",IFERROR($G14/'DATA ENTRY'!$G14,"")) | I14: =IF($B14="","",IF($H14="","Not entered",IF($H14>=0.25,"Strong",IF($H14>=0.15,"Adequate",IF($H14>=0.05,"Caution","High-risk"))))) | J14: =IF(OR($B14="",'DATA ENTRY'!$J14="",'DATA ENTRY'!$G14=""),"",IFERROR('DATA ENTRY'!$J14/'DATA ENTRY'!$G14,"")) | K14: =IF($B14="","",IF($J14="","Not entered",IF($J14>=0.08,"Strong",IF($J14>=0.03,"Adequate",IF($J14>=0,"Caution","High-risk"))))) | L14: =IF(OR($B14="",'DATA ENTRY'!$J14="",'DATA ENTRY'!$Q14=""),"",IFERROR('DATA ENTRY'!$J14/'DATA ENTRY'!$Q14,"")) | M14: =IF($B14="","",IF($L14="","Not entered",IF($L14>=0.1,"Strong",IF($L14>=0.05,"Adequate",IF($L14>=0,"Caution","High-risk"))))) | N14: =IF(OR($B14="",'DATA ENTRY'!$J14="",'DATA ENTRY'!$U14="",'DATA ENTRY'!$U14<=0),"",IFERROR('DATA ENTRY'!$J14/'DATA ENTRY'!$U14,"")) | O14: =IF($B14="","",IF(OR('DATA ENTRY'!$J14="",'DATA ENTRY'!$U14=""),"Not entered",IF('DATA ENTRY'!$U14<=0,"High-risk",IF($N14>=0.15,"Strong",IF($N14>=0.08,"Adequate",IF($N14>=0,"Caution","High-risk")))))) | P14: =IF(OR($B14="",'DATA ENTRY'!$K14="",'DATA ENTRY'!$R14=""),"",IFERROR('DATA ENTRY'!$K14/'DATA ENTRY'!$R14,"")) | Q14: =IF($B14="","",IF($P14="","Not entered",IF($P14>=1.5,"Strong",IF($P14>=1.2,"Adequate",IF($P14>=1,"Caution","High-risk"))))) | R14: =IF(OR($B14="",'DATA ENTRY'!$K14="",'DATA ENTRY'!$R14=""),"",IFERROR(('DATA ENTRY'!$K14-IF('DATA ENTRY'!$O14="",0,'DATA ENTRY'!$O14))/'DATA ENTRY'!$R14,"")) | S14: =IF($B14="","",IF($R14="","Not entered",IF($R14>=1,"Strong",IF($R14>=0.8,"Adequate",IF($R14>=0.6,"Caution","High-risk"))))) | T14: =IF(OR($B14="",'DATA ENTRY'!$T14="",'DATA ENTRY'!$U14="",'DATA ENTRY'!$U14<=0),"",IFERROR('DATA ENTRY'!$T14/'DATA ENTRY'!$U14,"")) | U14: =IF($B14="","",IF(OR('DATA ENTRY'!$T14="",'DATA ENTRY'!$U14=""),"Not entered",IF('DATA ENTRY'!$U14<=0,"High-risk",IF($T14<=1,"Strong",IF($T14<=1.5,"Adequate",IF($T14<=2,"Caution","High-risk")))))) | V14: =IF(OR($B14="",'DATA ENTRY'!$U14="",'DATA ENTRY'!$Q14=""),"",IFERROR('DATA ENTRY'!$U14/'DATA ENTRY'!$Q14,"")) | W14: =IF($B14="","",IF($V14="","Not entered",IF($V14>=0.5,"Strong",IF($V14>=0.3,"Adequate",IF($V14>=0.2,"Caution","High-risk"))))) | X14: =IF(OR($B14="",'DATA ENTRY'!$G14="",'DATA ENTRY'!$M14=""),"",IF('DATA ENTRY'!$N14<>"",'DATA ENTRY'!$G14/AVERAGE('DATA ENTRY'!$M14,'DATA ENTRY'!$N14),IFERROR('DATA ENTRY'!$G14/'DATA ENTRY'!$M14,""))) | Y14: =IF($X14="","",IFERROR(365/$X14,"")) | Z14: =IF($B14="","",IF($X14="","Not entered",IF($Y14<=60,"Strong",IF($Y14<=90,"Adequate",IF($Y14<=120,"Caution","High-risk"))))) | AA14: =IF(OR($B14="",'DATA ENTRY'!$G14="",'DATA ENTRY'!$Q14=""),"",IFERROR('DATA ENTRY'!$G14/'DATA ENTRY'!$Q14,"")) | AB14: =IF($B14="","",IF($AA14="","Not entered",IF($AA14>=1.5,"Strong",IF($AA14>=1,"Adequate",IF($AA14>=0.5,"Caution","High-risk"))))) | AC14: =IF(OR($B14="",'DATA ENTRY'!$K14="",'DATA ENTRY'!$R14=""),"",'DATA ENTRY'!$K14-'DATA ENTRY'!$R14) | AD14: =IF($B14="","",IF($AC14="","Not entered",IF($AC14<0,"High-risk",IF($AC14=0,"Caution",IF('DATA ENTRY'!$L14="","Adequate",IFERROR(IF('DATA ENTRY'!$L14/'DATA ENTRY'!$R14>=0.25,"Strong","Adequate"),"Adequate")))))) | AE14: =IF($B14="","",IF(OR('DATA ENTRY'!$W14="",'DATA ENTRY'!$W14=0),"N/A",IF('DATA ENTRY'!$V14="","",IFERROR('DATA ENTRY'!$V14/'DATA ENTRY'!$W14,"")))) | AF14: =IF($B14="","",IF($AE14="N/A","Not applicable",IF($AE14="","Not entered",IF($AE14>=4,"Strong",IF($AE14>=2.5,"Adequate",IF($AE14>=1.5,"Caution","High-risk")))))) | AG14: =IF($B14="","",IFERROR(ROUND((COUNTIF($I14:$AF14,"Strong")*4+COUNTIF($I14:$AF14,"Adequate")*3+COUNTIF($I14:$AF14,"Caution")*2+COUNTIF($I14:$AF14,"High-risk")*1)/(COUNTIF($I14:$AF14,"Strong")+COUNTIF($I14:$AF14,"Adequate")+COUNTIF($I14:$AF14,"Caution")+COUNTIF($I14:$AF14,"High-risk")),2),"")) | AH14: =IF($B14="","",IF(AND(ISNUMBER('DATA ENTRY'!$U14),'DATA ENTRY'!$U14<=0),"Financially stretched",IF($AG14="","Insufficient data",IF(AND(ISNUMBER('DATA ENTRY'!$J14),'DATA ENTRY'!$J14<0),IF($AG14>=2,"Adequate with caution","Financially stretched"),IF($AG14>=3.5,"Financially strong",IF($AG14>=2.75,"Financially adequate",IF($AG14>=2,"Adequate with caution","Financially stretched"))))))) | AI14: =IF($B14="","",IF(AND(ISNUMBER('DATA ENTRY'!$U14),'DATA ENTRY'!$U14<=0),"Negative equity — possible insolvency",IF(AND(ISNUMBER('DATA ENTRY'!$J14),'DATA ENTRY'!$J14<0),"Loss position",IF(AND(ISNUMBER($P14),$P14<1),"Current liabilities exceed current assets",IF(AND(ISNUMBER($T14),$T14>2),"High leverage",IF(AND(ISNUMBER($Y14),$Y14>120),"Slow receivables collection",IF(AND(ISNUMBER($AC14),$AC14<0),"Negative working capital",IF(OR('DATA ENTRY'!$E14="Unaudited",'DATA ENTRY'!$E14="Banker Letter Only",'DATA ENTRY'!$E14="Management Accounts"),"Statement status limits weight on ratios","No major red flag from entered ratios"))))))))
A15: =IF('DATA ENTRY'!$B15<>"",'DATA ENTRY'!$A15,"") | B15: =IF('DATA ENTRY'!$B15<>"",'DATA ENTRY'!$B15,"") | C15: =IF('DATA ENTRY'!$B15<>"",'DATA ENTRY'!$C15,"") | D15: =IF('DATA ENTRY'!$B15<>"",'DATA ENTRY'!$D15,"") | E15: =IF('DATA ENTRY'!$B15<>"",'DATA ENTRY'!$E15,"") | F15: =IF($B15="","",IF('DATA ENTRY'!$Y15="Yes","Checked",IF('DATA ENTRY'!$Y15="No","Needs check","Not marked"))) | G15: =IF($B15="","",IF('DATA ENTRY'!$I15<>"",'DATA ENTRY'!$I15,IF(AND('DATA ENTRY'!$G15<>"",'DATA ENTRY'!$H15<>""),'DATA ENTRY'!$G15-'DATA ENTRY'!$H15,""))) | H15: =IF(OR($B15="",$G15="",'DATA ENTRY'!$G15=""),"",IFERROR($G15/'DATA ENTRY'!$G15,"")) | I15: =IF($B15="","",IF($H15="","Not entered",IF($H15>=0.25,"Strong",IF($H15>=0.15,"Adequate",IF($H15>=0.05,"Caution","High-risk"))))) | J15: =IF(OR($B15="",'DATA ENTRY'!$J15="",'DATA ENTRY'!$G15=""),"",IFERROR('DATA ENTRY'!$J15/'DATA ENTRY'!$G15,"")) | K15: =IF($B15="","",IF($J15="","Not entered",IF($J15>=0.08,"Strong",IF($J15>=0.03,"Adequate",IF($J15>=0,"Caution","High-risk"))))) | L15: =IF(OR($B15="",'DATA ENTRY'!$J15="",'DATA ENTRY'!$Q15=""),"",IFERROR('DATA ENTRY'!$J15/'DATA ENTRY'!$Q15,"")) | M15: =IF($B15="","",IF($L15="","Not entered",IF($L15>=0.1,"Strong",IF($L15>=0.05,"Adequate",IF($L15>=0,"Caution","High-risk"))))) | N15: =IF(OR($B15="",'DATA ENTRY'!$J15="",'DATA ENTRY'!$U15="",'DATA ENTRY'!$U15<=0),"",IFERROR('DATA ENTRY'!$J15/'DATA ENTRY'!$U15,"")) | O15: =IF($B15="","",IF(OR('DATA ENTRY'!$J15="",'DATA ENTRY'!$U15=""),"Not entered",IF('DATA ENTRY'!$U15<=0,"High-risk",IF($N15>=0.15,"Strong",IF($N15>=0.08,"Adequate",IF($N15>=0,"Caution","High-risk")))))) | P15: =IF(OR($B15="",'DATA ENTRY'!$K15="",'DATA ENTRY'!$R15=""),"",IFERROR('DATA ENTRY'!$K15/'DATA ENTRY'!$R15,"")) | Q15: =IF($B15="","",IF($P15="","Not entered",IF($P15>=1.5,"Strong",IF($P15>=1.2,"Adequate",IF($P15>=1,"Caution","High-risk"))))) | R15: =IF(OR($B15="",'DATA ENTRY'!$K15="",'DATA ENTRY'!$R15=""),"",IFERROR(('DATA ENTRY'!$K15-IF('DATA ENTRY'!$O15="",0,'DATA ENTRY'!$O15))/'DATA ENTRY'!$R15,"")) | S15: =IF($B15="","",IF($R15="","Not entered",IF($R15>=1,"Strong",IF($R15>=0.8,"Adequate",IF($R15>=0.6,"Caution","High-risk"))))) | T15: =IF(OR($B15="",'DATA ENTRY'!$T15="",'DATA ENTRY'!$U15="",'DATA ENTRY'!$U15<=0),"",IFERROR('DATA ENTRY'!$T15/'DATA ENTRY'!$U15,"")) | U15: =IF($B15="","",IF(OR('DATA ENTRY'!$T15="",'DATA ENTRY'!$U15=""),"Not entered",IF('DATA ENTRY'!$U15<=0,"High-risk",IF($T15<=1,"Strong",IF($T15<=1.5,"Adequate",IF($T15<=2,"Caution","High-risk")))))) | V15: =IF(OR($B15="",'DATA ENTRY'!$U15="",'DATA ENTRY'!$Q15=""),"",IFERROR('DATA ENTRY'!$U15/'DATA ENTRY'!$Q15,"")) | W15: =IF($B15="","",IF($V15="","Not entered",IF($V15>=0.5,"Strong",IF($V15>=0.3,"Adequate",IF($V15>=0.2,"Caution","High-risk"))))) | X15: =IF(OR($B15="",'DATA ENTRY'!$G15="",'DATA ENTRY'!$M15=""),"",IF('DATA ENTRY'!$N15<>"",'DATA ENTRY'!$G15/AVERAGE('DATA ENTRY'!$M15,'DATA ENTRY'!$N15),IFERROR('DATA ENTRY'!$G15/'DATA ENTRY'!$M15,""))) | Y15: =IF($X15="","",IFERROR(365/$X15,"")) | Z15: =IF($B15="","",IF($X15="","Not entered",IF($Y15<=60,"Strong",IF($Y15<=90,"Adequate",IF($Y15<=120,"Caution","High-risk"))))) | AA15: =IF(OR($B15="",'DATA ENTRY'!$G15="",'DATA ENTRY'!$Q15=""),"",IFERROR('DATA ENTRY'!$G15/'DATA ENTRY'!$Q15,"")) | AB15: =IF($B15="","",IF($AA15="","Not entered",IF($AA15>=1.5,"Strong",IF($AA15>=1,"Adequate",IF($AA15>=0.5,"Caution","High-risk"))))) | AC15: =IF(OR($B15="",'DATA ENTRY'!$K15="",'DATA ENTRY'!$R15=""),"",'DATA ENTRY'!$K15-'DATA ENTRY'!$R15) | AD15: =IF($B15="","",IF($AC15="","Not entered",IF($AC15<0,"High-risk",IF($AC15=0,"Caution",IF('DATA ENTRY'!$L15="","Adequate",IFERROR(IF('DATA ENTRY'!$L15/'DATA ENTRY'!$R15>=0.25,"Strong","Adequate"),"Adequate")))))) | AE15: =IF($B15="","",IF(OR('DATA ENTRY'!$W15="",'DATA ENTRY'!$W15=0),"N/A",IF('DATA ENTRY'!$V15="","",IFERROR('DATA ENTRY'!$V15/'DATA ENTRY'!$W15,"")))) | AF15: =IF($B15="","",IF($AE15="N/A","Not applicable",IF($AE15="","Not entered",IF($AE15>=4,"Strong",IF($AE15>=2.5,"Adequate",IF($AE15>=1.5,"Caution","High-risk")))))) | AG15: =IF($B15="","",IFERROR(ROUND((COUNTIF($I15:$AF15,"Strong")*4+COUNTIF($I15:$AF15,"Adequate")*3+COUNTIF($I15:$AF15,"Caution")*2+COUNTIF($I15:$AF15,"High-risk")*1)/(COUNTIF($I15:$AF15,"Strong")+COUNTIF($I15:$AF15,"Adequate")+COUNTIF($I15:$AF15,"Caution")+COUNTIF($I15:$AF15,"High-risk")),2),"")) | AH15: =IF($B15="","",IF(AND(ISNUMBER('DATA ENTRY'!$U15),'DATA ENTRY'!$U15<=0),"Financially stretched",IF($AG15="","Insufficient data",IF(AND(ISNUMBER('DATA ENTRY'!$J15),'DATA ENTRY'!$J15<0),IF($AG15>=2,"Adequate with caution","Financially stretched"),IF($AG15>=3.5,"Financially strong",IF($AG15>=2.75,"Financially adequate",IF($AG15>=2,"Adequate with caution","Financially stretched"))))))) | AI15: =IF($B15="","",IF(AND(ISNUMBER('DATA ENTRY'!$U15),'DATA ENTRY'!$U15<=0),"Negative equity — possible insolvency",IF(AND(ISNUMBER('DATA ENTRY'!$J15),'DATA ENTRY'!$J15<0),"Loss position",IF(AND(ISNUMBER($P15),$P15<1),"Current liabilities exceed current assets",IF(AND(ISNUMBER($T15),$T15>2),"High leverage",IF(AND(ISNUMBER($Y15),$Y15>120),"Slow receivables collection",IF(AND(ISNUMBER($AC15),$AC15<0),"Negative working capital",IF(OR('DATA ENTRY'!$E15="Unaudited",'DATA ENTRY'!$E15="Banker Letter Only",'DATA ENTRY'!$E15="Management Accounts"),"Statement status limits weight on ratios","No major red flag from entered ratios"))))))))
